<sdf version='1.6'>
  <world name='default'>
    <light name='sun' type='directional'>
      <cast_shadows>1</cast_shadows>
      <pose frame=''>0 0 10 0 -0 0</pose>
      <diffuse>0.8 0.8 0.8 1</diffuse>
      <specular>0.1 0.1 0.1 1</specular>
      <attenuation>
        <range>1000</range>
        <constant>0.9</constant>
        <linear>0.01</linear>
        <quadratic>0.001</quadratic>
      </attenuation>
      <direction>-0.5 0.5 -1</direction>
    </light>
    <model name='ground_plane'>
      <static>1</static>
      <link name='link'>
        <collision name='collision'>
          <geometry>
            <plane>
              <normal>0 0 1</normal>
              <size>100 100</size>
            </plane>
          </geometry>
          <surface>
            <friction>
              <ode>
                <mu>100</mu>
                <mu2>50</mu2>
              </ode>
              <torsional>
                <ode/>
              </torsional>
            </friction>
            <contact>
              <ode/>
            </contact>
            <bounce/>
          </surface>
          <max_contacts>10</max_contacts>
        </collision>
        <visual name='visual'>
          <cast_shadows>0</cast_shadows>
          <geometry>
            <plane>
              <normal>0 0 1</normal>
              <size>100 100</size>
            </plane>
          </geometry>
          <material>
            <script>
              <uri>file://media/materials/scripts/gazebo.material</uri>
              <name>Gazebo/Grey</name>
            </script>
          </material>
        </visual>
        <self_collide>0</self_collide>
        <kinematic>0</kinematic>
        <gravity>1</gravity>
      </link>
    </model>
    <gravity>0 0 -9.8</gravity>
    <magnetic_field>6e-06 2.3e-05 -4.2e-05</magnetic_field>
    <atmosphere type='adiabatic'/>
    <physics name='default_physics' default='0' type='ode'>
      <max_step_size>0.001</max_step_size>
      <real_time_factor>1</real_time_factor>
      <real_time_update_rate>1000</real_time_update_rate>
    </physics>
    <scene>
      <ambient>0.4 0.4 0.4 1</ambient>
      <background>0.7 0.7 0.7 1</background>
      <shadows>1</shadows>
    </scene>
    <spherical_coordinates>
      <surface_model>EARTH_WGS84</surface_model>
      <latitude_deg>0</latitude_deg>
      <longitude_deg>0</longitude_deg>
      <elevation>0</elevation>
      <heading_deg>0</heading_deg>
    </spherical_coordinates>
    <model name='Finderbot_Lidar'>
      <model name='Finderbot'>
        <link name='chassis'>
          <inertial>
            <mass>0.961969</mass>
            <inertia>
              <ixx>0.154347</ixx>
              <ixy>0</ixy>
              <ixz>0</ixz>
              <iyy>0.154347</iyy>
              <iyz>0</iyz>
              <izz>0.160328</izz>
            </inertia>
            <pose frame=''>0 0 0 0 -0 0</pose>
          </inertial>
          <pose frame=''>0.070818 -0.081206 0.487978 0 -0 0</pose>
          <gravity>1</gravity>
          <self_collide>0</self_collide>
          <kinematic>0</kinematic>
          <enable_wind>0</enable_wind>
          <visual name='visual'>
            <pose frame=''>0 0 0 0 -0 0</pose>
            <geometry>
              <box>
                <size>0.37 0.66 0.17</size>
              </box>
            </geometry>
            <material>
              <lighting>1</lighting>
              <script>
                <uri>file://media/materials/scripts/gazebo.material</uri>
                <name>Gazebo/Grey</name>
              </script>
              <shader type='vertex'>
                <normal_map>__default__</normal_map>
              </shader>
              <ambient>0.3 0.3 0.3 1</ambient>
              <diffuse>0.7 0.7 0.7 1</diffuse>
              <specular>0.01 0.01 0.01 1</specular>
              <emissive>0 0 0 1</emissive>
            </material>
            <transparency>0</transparency>
            <cast_shadows>1</cast_shadows>
          </visual>
          <collision name='collision'>
            <laser_retro>0</laser_retro>
            <max_contacts>10</max_contacts>
            <pose frame=''>0 0 0 0 -0 0</pose>
            <geometry>
              <box>
                <size>0.37 0.66 0.17</size>
              </box>
            </geometry>
            <surface>
              <friction>
                <ode>
                  <mu>1</mu>
                  <mu2>1</mu2>
                  <fdir1>0 0 0</fdir1>
                  <slip1>0</slip1>
                  <slip2>0</slip2>
                </ode>
                <torsional>
                  <coefficient>1</coefficient>
                  <patch_radius>0</patch_radius>
                  <surface_radius>0</surface_radius>
                  <use_patch_radius>1</use_patch_radius>
                  <ode>
                    <slip>0</slip>
                  </ode>
                </torsional>
              </friction>
              <bounce>
                <restitution_coefficient>0</restitution_coefficient>
                <threshold>1e+06</threshold>
              </bounce>
              <contact>
                <collide_without_contact>0</collide_without_contact>
                <collide_without_contact_bitmask>1</collide_without_contact_bitmask>
                <collide_bitmask>1</collide_bitmask>
                <ode>
                  <soft_cfm>0</soft_cfm>
                  <soft_erp>0.2</soft_erp>
                  <kp>1e+13</kp>
                  <kd>1</kd>
                  <max_vel>0.01</max_vel>
                  <min_depth>0</min_depth>
                </ode>
                <bullet>
                  <split_impulse>1</split_impulse>
                  <split_impulse_penetration_threshold>-0.01</split_impulse_penetration_threshold>
                  <soft_cfm>0</soft_cfm>
                  <soft_erp>0.2</soft_erp>
                  <kp>1e+13</kp>
                  <kd>1</kd>
                </bullet>
              </contact>
            </surface>
          </collision>
        </link>
        <link name='back_right_wheel'>
          <inertial>
            <mass>1</mass>
            <inertia>
              <ixx>0.145833</ixx>
              <ixy>0</ixy>
              <ixz>0</ixz>
              <iyy>0.145833</iyy>
              <iyz>0</iyz>
              <izz>0.125</izz>
            </inertia>
            <pose frame=''>0 0 0 0 -0 0</pose>
          </inertial>
          <pose frame=''>0.291009 -0.311094 0.387978 1.57 -0 1.57</pose>
          <gravity>1</gravity>
          <self_collide>0</self_collide>
          <kinematic>0</kinematic>
          <enable_wind>0</enable_wind>
          <visual name='visual'>
            <pose frame=''>0 0 0 0 -0 0</pose>
            <geometry>
              <cylinder>
                <radius>0.1</radius>
                <length>0.07</length>
              </cylinder>
            </geometry>
            <material>
              <lighting>1</lighting>
              <script>
                <uri>file://media/materials/scripts/gazebo.material</uri>
                <name>Gazebo/Grey</name>
              </script>
              <shader type='vertex'>
                <normal_map>__default__</normal_map>
              </shader>
              <ambient>0.3 0.3 0.3 1</ambient>
              <diffuse>0.7 0.7 0.7 1</diffuse>
              <specular>0.01 0.01 0.01 1</specular>
              <emissive>0 0 0 1</emissive>
            </material>
            <transparency>0</transparency>
            <cast_shadows>1</cast_shadows>
          </visual>
          <collision name='collision'>
            <laser_retro>0</laser_retro>
            <max_contacts>10</max_contacts>
            <pose frame=''>0 0 0 0 -0 0</pose>
            <geometry>
              <cylinder>
                <radius>0.1</radius>
                <length>0.07</length>
              </cylinder>
            </geometry>
            <surface>
              <friction>
                <ode>
                  <mu>1</mu>
                  <mu2>1</mu2>
                  <fdir1>0 0 0</fdir1>
                  <slip1>0</slip1>
                  <slip2>0</slip2>
                </ode>
                <torsional>
                  <coefficient>1</coefficient>
                  <patch_radius>0</patch_radius>
                  <surface_radius>0</surface_radius>
                  <use_patch_radius>1</use_patch_radius>
                  <ode>
                    <slip>0</slip>
                  </ode>
                </torsional>
              </friction>
              <bounce>
                <restitution_coefficient>0</restitution_coefficient>
                <threshold>1e+06</threshold>
              </bounce>
              <contact>
                <collide_without_contact>0</collide_without_contact>
                <collide_without_contact_bitmask>1</collide_without_contact_bitmask>
                <collide_bitmask>1</collide_bitmask>
                <ode>
                  <soft_cfm>0</soft_cfm>
                  <soft_erp>0.2</soft_erp>
                  <kp>1e+13</kp>
                  <kd>1</kd>
                  <max_vel>0.01</max_vel>
                  <min_depth>0</min_depth>
                </ode>
                <bullet>
                  <split_impulse>1</split_impulse>
                  <split_impulse_penetration_threshold>-0.01</split_impulse_penetration_threshold>
                  <soft_cfm>0</soft_cfm>
                  <soft_erp>0.2</soft_erp>
                  <kp>1e+13</kp>
                  <kd>1</kd>
                </bullet>
              </contact>
            </surface>
          </collision>
        </link>
        <link name='front_right_wheel'>
          <inertial>
            <mass>1</mass>
            <inertia>
              <ixx>0.145833</ixx>
              <ixy>0</ixy>
              <ixz>0</ixz>
              <iyy>0.145833</iyy>
              <iyz>0</iyz>
              <izz>0.125</izz>
            </inertia>
            <pose frame=''>0 0 0 0 -0 0</pose>
          </inertial>
          <pose frame=''>0.290977 0.148766 0.387978 1.57 -0 1.57</pose>
          <gravity>1</gravity>
          <self_collide>0</self_collide>
          <kinematic>0</kinematic>
          <enable_wind>0</enable_wind>
          <visual name='visual'>
            <pose frame=''>0 0 0 0 -0 0</pose>
            <geometry>
              <cylinder>
                <radius>0.1</radius>
                <length>0.07</length>
              </cylinder>
            </geometry>
            <material>
              <lighting>1</lighting>
              <script>
                <uri>file://media/materials/scripts/gazebo.material</uri>
                <name>Gazebo/Grey</name>
              </script>
              <shader type='vertex'>
                <normal_map>__default__</normal_map>
              </shader>
              <ambient>0.3 0.3 0.3 1</ambient>
              <diffuse>0.7 0.7 0.7 1</diffuse>
              <specular>0.01 0.01 0.01 1</specular>
              <emissive>0 0 0 1</emissive>
            </material>
            <transparency>0</transparency>
            <cast_shadows>1</cast_shadows>
          </visual>
          <collision name='collision'>
            <laser_retro>0</laser_retro>
            <max_contacts>10</max_contacts>
            <pose frame=''>0 0 0 0 -0 0</pose>
            <geometry>
              <cylinder>
                <radius>0.1</radius>
                <length>0.07</length>
              </cylinder>
            </geometry>
            <surface>
              <friction>
                <ode>
                  <mu>1</mu>
                  <mu2>1</mu2>
                  <fdir1>0 0 0</fdir1>
                  <slip1>0</slip1>
                  <slip2>0</slip2>
                </ode>
                <torsional>
                  <coefficient>1</coefficient>
                  <patch_radius>0</patch_radius>
                  <surface_radius>0</surface_radius>
                  <use_patch_radius>1</use_patch_radius>
                  <ode>
                    <slip>0</slip>
                  </ode>
                </torsional>
              </friction>
              <bounce>
                <restitution_coefficient>0</restitution_coefficient>
                <threshold>1e+06</threshold>
              </bounce>
              <contact>
                <collide_without_contact>0</collide_without_contact>
                <collide_without_contact_bitmask>1</collide_without_contact_bitmask>
                <collide_bitmask>1</collide_bitmask>
                <ode>
                  <soft_cfm>0</soft_cfm>
                  <soft_erp>0.2</soft_erp>
                  <kp>1e+13</kp>
                  <kd>1</kd>
                  <max_vel>0.01</max_vel>
                  <min_depth>0</min_depth>
                </ode>
                <bullet>
                  <split_impulse>1</split_impulse>
                  <split_impulse_penetration_threshold>-0.01</split_impulse_penetration_threshold>
                  <soft_cfm>0</soft_cfm>
                  <soft_erp>0.2</soft_erp>
                  <kp>1e+13</kp>
                  <kd>1</kd>
                </bullet>
              </contact>
            </surface>
          </collision>
        </link>
        <link name='back_left_wheel'>
          <inertial>
            <mass>1</mass>
            <inertia>
              <ixx>0.145833</ixx>
              <ixy>0</ixy>
              <ixz>0</ixz>
              <iyy>0.145833</iyy>
              <iyz>0</iyz>
              <izz>0.125</izz>
            </inertia>
            <pose frame=''>0 0 0 0 -0 0</pose>
          </inertial>
          <pose frame=''>-0.149341 -0.311178 0.387978 1.57 -0 1.57</pose>
          <gravity>1</gravity>
          <self_collide>0</self_collide>
          <kinematic>0</kinematic>
          <enable_wind>0</enable_wind>
          <visual name='visual'>
            <pose frame=''>0 0 0 0 -0 0</pose>
            <geometry>
              <cylinder>
                <radius>0.1</radius>
                <length>0.07</length>
              </cylinder>
            </geometry>
            <material>
              <lighting>1</lighting>
              <script>
                <uri>file://media/materials/scripts/gazebo.material</uri>
                <name>Gazebo/Grey</name>
              </script>
              <shader type='vertex'>
                <normal_map>__default__</normal_map>
              </shader>
              <ambient>0.3 0.3 0.3 1</ambient>
              <diffuse>0.7 0.7 0.7 1</diffuse>
              <specular>0.01 0.01 0.01 1</specular>
              <emissive>0 0 0 1</emissive>
            </material>
            <transparency>0</transparency>
            <cast_shadows>1</cast_shadows>
          </visual>
          <collision name='collision'>
            <laser_retro>0</laser_retro>
            <max_contacts>10</max_contacts>
            <pose frame=''>0 0 0 0 -0 0</pose>
            <geometry>
              <cylinder>
                <radius>0.1</radius>
                <length>0.07</length>
              </cylinder>
            </geometry>
            <surface>
              <friction>
                <ode>
                  <mu>1</mu>
                  <mu2>1</mu2>
                  <fdir1>0 0 0</fdir1>
                  <slip1>0</slip1>
                  <slip2>0</slip2>
                </ode>
                <torsional>
                  <coefficient>1</coefficient>
                  <patch_radius>0</patch_radius>
                  <surface_radius>0</surface_radius>
                  <use_patch_radius>1</use_patch_radius>
                  <ode>
                    <slip>0</slip>
                  </ode>
                </torsional>
              </friction>
              <bounce>
                <restitution_coefficient>0</restitution_coefficient>
                <threshold>1e+06</threshold>
              </bounce>
              <contact>
                <collide_without_contact>0</collide_without_contact>
                <collide_without_contact_bitmask>1</collide_without_contact_bitmask>
                <collide_bitmask>1</collide_bitmask>
                <ode>
                  <soft_cfm>0</soft_cfm>
                  <soft_erp>0.2</soft_erp>
                  <kp>1e+13</kp>
                  <kd>1</kd>
                  <max_vel>0.01</max_vel>
                  <min_depth>0</min_depth>
                </ode>
                <bullet>
                  <split_impulse>1</split_impulse>
                  <split_impulse_penetration_threshold>-0.01</split_impulse_penetration_threshold>
                  <soft_cfm>0</soft_cfm>
                  <soft_erp>0.2</soft_erp>
                  <kp>1e+13</kp>
                  <kd>1</kd>
                </bullet>
              </contact>
            </surface>
          </collision>
        </link>
        <link name='front_left_wheel'>
          <inertial>
            <mass>1</mass>
            <inertia>
              <ixx>0.145833</ixx>
              <ixy>0</ixy>
              <ixz>0</ixz>
              <iyy>0.145833</iyy>
              <iyz>0</iyz>
              <izz>0.125</izz>
            </inertia>
            <pose frame=''>0 0 0 0 -0 0</pose>
          </inertial>
          <pose frame=''>-0.149341 0.148766 0.387978 1.57 -0 1.57</pose>
          <gravity>1</gravity>
          <self_collide>0</self_collide>
          <kinematic>0</kinematic>
          <enable_wind>0</enable_wind>
          <visual name='visual'>
            <pose frame=''>0 0 0 0 -0 0</pose>
            <geometry>
              <cylinder>
                <radius>0.1</radius>
                <length>0.07</length>
              </cylinder>
            </geometry>
            <material>
              <lighting>1</lighting>
              <script>
                <uri>file://media/materials/scripts/gazebo.material</uri>
                <name>Gazebo/Grey</name>
              </script>
              <shader type='vertex'>
                <normal_map>__default__</normal_map>
              </shader>
              <ambient>0.3 0.3 0.3 1</ambient>
              <diffuse>0.7 0.7 0.7 1</diffuse>
              <specular>0.01 0.01 0.01 1</specular>
              <emissive>0 0 0 1</emissive>
            </material>
            <transparency>0</transparency>
            <cast_shadows>1</cast_shadows>
          </visual>
          <collision name='collision'>
            <laser_retro>0</laser_retro>
            <max_contacts>10</max_contacts>
            <pose frame=''>0 0 0 0 -0 0</pose>
            <geometry>
              <cylinder>
                <radius>0.1</radius>
                <length>0.07</length>
              </cylinder>
            </geometry>
            <surface>
              <friction>
                <ode>
                  <mu>1</mu>
                  <mu2>1</mu2>
                  <fdir1>0 0 0</fdir1>
                  <slip1>0</slip1>
                  <slip2>0</slip2>
                </ode>
                <torsional>
                  <coefficient>1</coefficient>
                  <patch_radius>0</patch_radius>
                  <surface_radius>0</surface_radius>
                  <use_patch_radius>1</use_patch_radius>
                  <ode>
                    <slip>0</slip>
                  </ode>
                </torsional>
              </friction>
              <bounce>
                <restitution_coefficient>0</restitution_coefficient>
                <threshold>1e+06</threshold>
              </bounce>
              <contact>
                <collide_without_contact>0</collide_without_contact>
                <collide_without_contact_bitmask>1</collide_without_contact_bitmask>
                <collide_bitmask>1</collide_bitmask>
                <ode>
                  <soft_cfm>0</soft_cfm>
                  <soft_erp>0.2</soft_erp>
                  <kp>1e+13</kp>
                  <kd>1</kd>
                  <max_vel>0.01</max_vel>
                  <min_depth>0</min_depth>
                </ode>
                <bullet>
                  <split_impulse>1</split_impulse>
                  <split_impulse_penetration_threshold>-0.01</split_impulse_penetration_threshold>
                  <soft_cfm>0</soft_cfm>
                  <soft_erp>0.2</soft_erp>
                  <kp>1e+13</kp>
                  <kd>1</kd>
                </bullet>
              </contact>
            </surface>
          </collision>
        </link>
        <joint name='back_right_joint' type='revolute'>
          <parent>chassis</parent>
          <child>back_right_wheel</child>
          <pose frame=''>0 0 0 0 -0 0</pose>
          <axis>
            <xyz>0 0 -1</xyz>
            <use_parent_model_frame>0</use_parent_model_frame>
            <limit>
              <lower>-1.79769e+308</lower>
              <upper>1.79769e+308</upper>
              <effort>-1</effort>
              <velocity>-1</velocity>
            </limit>
            <dynamics>
              <spring_reference>0</spring_reference>
              <spring_stiffness>0</spring_stiffness>
              <damping>0</damping>
              <friction>0</friction>
            </dynamics>
          </axis>
          <physics>
            <ode>
              <limit>
                <cfm>0</cfm>
                <erp>0.2</erp>
              </limit>
              <suspension>
                <cfm>0</cfm>
                <erp>0.2</erp>
              </suspension>
            </ode>
          </physics>
        </joint>
        <joint name='front_right_joint' type='revolute'>
          <parent>chassis</parent>
          <child>front_right_wheel</child>
          <pose frame=''>0 0 0 0 -0.01 0</pose>
          <axis>
            <xyz>0 0 -1</xyz>
            <use_parent_model_frame>0</use_parent_model_frame>
            <limit>
              <lower>-1.79769e+308</lower>
              <upper>1.79769e+308</upper>
              <effort>-1</effort>
              <velocity>-1</velocity>
            </limit>
            <dynamics>
              <spring_reference>0</spring_reference>
              <spring_stiffness>0</spring_stiffness>
              <damping>0</damping>
            </dynamics>
          </axis>
          <physics>
            <ode>
              <limit>
                <cfm>0</cfm>
                <erp>0.2</erp>
              </limit>
              <suspension>
                <cfm>0</cfm>
                <erp>0.2</erp>
              </suspension>
            </ode>
          </physics>
        </joint>
        <joint name='back_left_joint' type='revolute'>
          <parent>chassis</parent>
          <child>back_left_wheel</child>
          <pose frame=''>0 0 0 0 -0 0</pose>
          <axis>
            <xyz>0 0 -1</xyz>
            <use_parent_model_frame>0</use_parent_model_frame>
            <limit>
              <lower>-1.79769e+308</lower>
              <upper>1.79769e+308</upper>
              <effort>-1</effort>
              <velocity>-1</velocity>
            </limit>
            <dynamics>
              <spring_reference>0</spring_reference>
              <spring_stiffness>0</spring_stiffness>
              <damping>0</damping>
            </dynamics>
          </axis>
          <physics>
            <ode>
              <limit>
                <cfm>0</cfm>
                <erp>0.2</erp>
              </limit>
              <suspension>
                <cfm>0</cfm>
                <erp>0.2</erp>
              </suspension>
            </ode>
          </physics>
        </joint>
        <joint name='front_left_joint' type='revolute'>
          <parent>chassis</parent>
          <child>front_left_wheel</child>
          <pose frame=''>0 0 0 0 -0 0</pose>
          <axis>
            <xyz>0 0 -1</xyz>
            <use_parent_model_frame>0</use_parent_model_frame>
            <limit>
              <lower>-1.79769e+308</lower>
              <upper>1.79769e+308</upper>
              <effort>-1</effort>
              <velocity>-1</velocity>
            </limit>
            <dynamics>
              <spring_reference>0</spring_reference>
              <spring_stiffness>0</spring_stiffness>
              <damping>0</damping>
            </dynamics>
          </axis>
          <physics>
            <ode>
              <limit>
                <cfm>0</cfm>
                <erp>0.2</erp>
              </limit>
              <suspension>
                <cfm>0</cfm>
                <erp>0.2</erp>
              </suspension>
            </ode>
          </physics>
        </joint>
        <static>0</static>
        <allow_auto_disable>1</allow_auto_disable>
        <pose frame=''>-0.035457 -0.072805 -0.312323 0 -0 0</pose>
        <plugin name='skid_steer_drive_controller' filename='libgazebo_ros_skid_steer_drive.so'>
          <updateRate>100.0</updateRate>
          <leftFrontJoint>front_left_joint</leftFrontJoint>
          <leftRearJoint>back_left_joint</leftRearJoint>
          <rightFrontJoint>front_right_joint</rightFrontJoint>
          <rightRearJoint>back_right_joint</rightRearJoint>
          <wheelDiameter>0.1</wheelDiameter>
          <wheelSeparation>0.37</wheelSeparation>
          <robotBaseFrame>chassis</robotBaseFrame>
          <torque>20</torque>
          <commandTopic>finderbot_cmd_vel</commandTopic>
          <odometryTopic>finderbot_odom</odometryTopic>
          <broadcastTF>False</broadcastTF>
        </plugin>
        <plugin name='imu_plugin' filename='libgazebo_ros_imu.so'>
          <alwaysOn>true</alwaysOn>
          <bodyName>chassis</bodyName>
          <topicName>finderbot_imu</topicName>
          <serviceName>imu_service</serviceName>
          <gaussianNoise>0.0</gaussianNoise>
          <updateRate>20.0</updateRate>
        </plugin>
      </model>
      <model name='hokuyo_utm30lx'>
        <pose frame=''>0.035457 0.072805 0.312324 0 -0 1.5892</pose>
        <link name='link'>
          <inertial>
            <mass>0.27</mass>
            <inertia>
              <ixx>0.0002632</ixx>
              <iyy>0.0002632</iyy>
              <izz>0.000162</izz>
              <ixy>0</ixy>
              <ixz>0</ixz>
              <iyz>0</iyz>
            </inertia>
          </inertial>
          <visual name='visual'>
            <pose frame=''>0 0 0 0 -0 0</pose>
            <geometry>
              <mesh>
                <uri>model://hokuyo_utm30lx/meshes/hokuyo_utm_30lx.dae</uri>
              </mesh>
            </geometry>
          </visual>
          <collision name='hokuyo_collision'>
            <pose frame=''>0 0 -0.0115 0 -0 0</pose>
            <geometry>
              <box>
                <size>0.058 0.058 0.087</size>
              </box>
            </geometry>
            <max_contacts>10</max_contacts>
            <surface>
              <contact>
                <ode/>
              </contact>
              <bounce/>
              <friction>
                <torsional>
                  <ode/>
                </torsional>
                <ode/>
              </friction>
            </surface>
          </collision>
          <sensor name='lidar' type='ray'>
            <pose frame=''>0 0 0.0205 0 -0 0</pose>
            <ray>
              <scan>
                <horizontal>
                  <samples>260</samples>
                  <min_angle>-2.2689</min_angle>
                  <max_angle>2.2689</max_angle>
                  <resolution>1</resolution>
                </horizontal>
                <vertical>
                  <samples>1</samples>
                  <min_angle>0</min_angle>
                  <max_angle>0</max_angle>
                </vertical>
              </scan>
              <range>
                <min>0.08</min>
                <max>30</max>
                <resolution>0.01</resolution>
              </range>
              <noise>
                <type>gaussian</type>
                <mean>0</mean>
                <stddev>0.004</stddev>
              </noise>
            </ray>
            <plugin name='gazebo_hokuyo' filename='libgazebo_ros_laser.so'>
              <topicName>/hokuyo_data</topicName>
              <robotNamespace>hokuyo</robotNamespace>
              <frameName>hokuyo_frame</frameName>
            </plugin>
            <update_rate>30</update_rate>
            <visualize>1</visualize>
            <always_on>1</always_on>
          </sensor>
          <self_collide>0</self_collide>
          <kinematic>0</kinematic>
          <gravity>1</gravity>
        </link>
      </model>
      <joint name='lidar_fixed_joint' type='fixed'>
        <parent>Finderbot::chassis</parent>
        <child>hokuyo_utm30lx::link</child>
        <pose frame=''>0 0 0 0 -0 0</pose>
        <physics>
          <ode>
            <limit>
              <cfm>0</cfm>
              <erp>0.2</erp>
            </limit>
            <suspension>
              <cfm>0</cfm>
              <erp>0.2</erp>
            </suspension>
          </ode>
        </physics>
      </joint>
      <static>0</static>
      <allow_auto_disable>1</allow_auto_disable>
      <pose frame=''>1.61971 1.59196 0 0 -0 0</pose>
    </model>
    <state world_name='default'>
      <sim_time>179 751000000</sim_time>
      <real_time>37 54984078</real_time>
      <wall_time>1512345926 533525835</wall_time>
      <iterations>36685</iterations>
      <model name='Finderbot_Lidar'>
        <pose frame=''>1.55199 2.2274 0.02437 -4e-06 4e-06 -0.012468</pose>
        <scale>1 1 1</scale>
        <model name='Finderbot'>
          <pose frame=''>1.51562 2.15504 -0.287952 -4e-06 4e-06 -0.012468</pose>
          <scale>1 1 1</scale>
          <link name='back_left_wheel'>
            <pose frame=''>1.36242 1.84575 0.100028 1.57 -0.007951 1.55754</pose>
            <velocity>0.0004 0.000381 -0.000137 -0.003886 0.004008 -0.000172</velocity>
            <acceleration>0.801518 0.780709 -0.27344 0.225201 1.39033 2.99111</acceleration>
            <wrench>0.801518 0.780709 -0.27344 0 -0 0</wrench>
          </link>
          <link name='back_right_wheel'>
            <pose frame=''>1.80273 1.84035 0.100026 1.57 0.000916 1.55753</pose>
            <velocity>0.000399 0.000302 -0.001902 -0.003961 0.004023 -0.00017</velocity>
            <acceleration>0.801116 0.69695 -3.80375 0.177168 1.36151 2.99494</acceleration>
            <wrench>0.801116 0.69695 -3.80375 0 -0 0</wrench>
          </link>
          <link name='chassis'>
            <pose frame=''>1.58543 2.07296 0.200026 -4e-06 4e-06 -0.012468</pose>
            <velocity>0.00083 0.000725 -0.001948 -0.003963 0.00403 -0.000168</velocity>
            <acceleration>1.62337 1.50565 -3.89612 1.49857 1.36417 2.9759</acceleration>
            <wrench>1.56163 1.44839 -3.74795 0 -0 0</wrench>
          </link>
          <link name='front_left_wheel'>
            <pose frame=''>1.36815 2.30566 0.100026 1.57 0.004401 1.55753</pose>
            <velocity>0.000476 0.000372 -0.001982 -0.003967 0.004 -0.000168</velocity>
            <acceleration>0.875468 0.762705 -3.96376 0.220059 1.40729 2.999</acceleration>
            <wrench>0.875468 0.762705 -3.96376 0 -0 0</wrench>
          </link>
          <link name='front_right_wheel'>
            <pose frame=''>1.80843 2.30017 0.100024 1.57 -0.000242 1.55753</pose>
            <velocity>0.000477 0.000302 -0.003752 -0.003957 0.004022 -0.000172</velocity>
            <acceleration>0.879258 0.697624 -7.50337 0.17156 1.36326 2.99082</acceleration>
            <wrench>0.879258 0.697624 -7.50337 0 -0 0</wrench>
          </link>
        </model>
        <model name='hokuyo_utm30lx'>
          <pose frame=''>1.58258 2.30402 0.312327 -4e-06 -4e-06 1.58947</pose>
          <scale>1 1 1</scale>
          <link name='link'>
            <pose frame=''>1.58835 2.29976 0.33669 4e-06 -5e-06 1.57673</pose>
            <velocity>0.000292 0.001678 -0.00046 -0.008272 0.004724 -0.00189</velocity>
            <acceleration>0.507916 3.41319 -0.92075 -0.835377 -0.022603 -0.467323</acceleration>
            <wrench>0.137137 0.921562 -0.248602 0 -0 0</wrench>
          </link>
        </model>
      </model>
      <model name='ground_plane'>
        <pose frame=''>0 0 0 0 -0 0</pose>
        <scale>1 1 1</scale>
        <link name='link'>
          <pose frame=''>0 0 0 0 -0 0</pose>
          <velocity>0 0 0 0 -0 0</velocity>
          <acceleration>0 0 0 0 -0 0</acceleration>
          <wrench>0 0 0 0 -0 0</wrench>
        </link>
      </model>
      <light name='sun'>
        <pose frame=''>0 0 10 0 -0 0</pose>
      </light>
    </state>
    <gui fullscreen='0'>
      <camera name='user_camera'>
        <pose frame=''>5.71518 -6.72067 14.9848 -0 1.17564 1.69219</pose>
        <view_controller>orbit</view_controller>
        <projection_type>perspective</projection_type>
      </camera>
    </gui>
  </world>
</sdf>
